[2024-09-01T15:33:58.406+0000] {local_task_job_runner.py:123} INFO - ::group::Pre task execution logs
[2024-09-01T15:33:58.424+0000] {taskinstance.py:2603} INFO - Dependencies all met for dep_context=non-requeueable deps ti=<TaskInstance: ml_pipeline.evaluate_model manual__2024-09-01T15:33:44.449486+00:00 [queued]>
[2024-09-01T15:33:58.433+0000] {taskinstance.py:2603} INFO - Dependencies all met for dep_context=requeueable deps ti=<TaskInstance: ml_pipeline.evaluate_model manual__2024-09-01T15:33:44.449486+00:00 [queued]>
[2024-09-01T15:33:58.434+0000] {taskinstance.py:2856} INFO - Starting attempt 1 of 2
[2024-09-01T15:33:58.448+0000] {taskinstance.py:2879} INFO - Executing <Task(PythonOperator): evaluate_model> on 2024-09-01 15:33:44.449486+00:00
[2024-09-01T15:33:58.457+0000] {warnings.py:112} WARNING - /home/***/.local/lib/python3.12/site-packages/***/task/task_runner/standard_task_runner.py:70: DeprecationWarning: This process (pid=1226) is multi-threaded, use of fork() may lead to deadlocks in the child.
  pid = os.fork()

[2024-09-01T15:33:58.458+0000] {standard_task_runner.py:104} INFO - Running: ['***', 'tasks', 'run', 'ml_pipeline', 'evaluate_model', 'manual__2024-09-01T15:33:44.449486+00:00', '--job-id', '97', '--raw', '--subdir', 'DAGS_FOLDER/ml_pipeline.py', '--cfg-path', '/tmp/tmpy_dk7u6e']
[2024-09-01T15:33:58.460+0000] {standard_task_runner.py:72} INFO - Started process 1235 to run task
[2024-09-01T15:33:58.460+0000] {standard_task_runner.py:105} INFO - Job 97: Subtask evaluate_model
[2024-09-01T15:33:58.513+0000] {task_command.py:467} INFO - Running <TaskInstance: ml_pipeline.evaluate_model manual__2024-09-01T15:33:44.449486+00:00 [running]> on host e851988aa96f
[2024-09-01T15:33:58.851+0000] {taskinstance.py:3122} INFO - Exporting env vars: AIRFLOW_CTX_DAG_OWNER='***' AIRFLOW_CTX_DAG_ID='ml_pipeline' AIRFLOW_CTX_TASK_ID='evaluate_model' AIRFLOW_CTX_EXECUTION_DATE='2024-09-01T15:33:44.449486+00:00' AIRFLOW_CTX_TRY_NUMBER='1' AIRFLOW_CTX_DAG_RUN_ID='manual__2024-09-01T15:33:44.449486+00:00'
[2024-09-01T15:33:58.852+0000] {logging_mixin.py:190} INFO - Task instance is in running state
[2024-09-01T15:33:58.853+0000] {logging_mixin.py:190} INFO -  Previous state of the Task instance: queued
[2024-09-01T15:33:58.853+0000] {logging_mixin.py:190} INFO - Current task name:evaluate_model state:running start_date:2024-09-01 15:33:58.425725+00:00
[2024-09-01T15:33:58.854+0000] {logging_mixin.py:190} INFO - Dag name:ml_pipeline and current dag run status:running
[2024-09-01T15:33:58.854+0000] {taskinstance.py:731} INFO - ::endgroup::
[2024-09-01T15:33:58.860+0000] {logging_mixin.py:190} INFO - Evaluating model with X_test shape: 4, y_test shape: 4
[2024-09-01T15:33:58.862+0000] {taskinstance.py:3301} ERROR - Task failed with exception
Traceback (most recent call last):
  File "/home/airflow/.local/lib/python3.12/site-packages/airflow/models/taskinstance.py", line 767, in _execute_task
    result = _execute_callable(context=context, **execute_callable_kwargs)
             ^^^^^^^^^^^^^^^^^^^^^^^^^^^^^^^^^^^^^^^^^^^^^^^^^^^^^^^^^^^^^
  File "/home/airflow/.local/lib/python3.12/site-packages/airflow/models/taskinstance.py", line 733, in _execute_callable
    return ExecutionCallableRunner(
           ^^^^^^^^^^^^^^^^^^^^^^^^
  File "/home/airflow/.local/lib/python3.12/site-packages/airflow/utils/operator_helpers.py", line 252, in run
    return self.func(*args, **kwargs)
           ^^^^^^^^^^^^^^^^^^^^^^^^^^
  File "/home/airflow/.local/lib/python3.12/site-packages/airflow/models/baseoperator.py", line 406, in wrapper
    return func(self, *args, **kwargs)
           ^^^^^^^^^^^^^^^^^^^^^^^^^^^
  File "/home/airflow/.local/lib/python3.12/site-packages/airflow/operators/python.py", line 238, in execute
    return_value = self.execute_callable()
                   ^^^^^^^^^^^^^^^^^^^^^^^
  File "/home/airflow/.local/lib/python3.12/site-packages/airflow/operators/python.py", line 256, in execute_callable
    return runner.run(*self.op_args, **self.op_kwargs)
           ^^^^^^^^^^^^^^^^^^^^^^^^^^^^^^^^^^^^^^^^^^^
  File "/home/airflow/.local/lib/python3.12/site-packages/airflow/utils/operator_helpers.py", line 252, in run
    return self.func(*args, **kwargs)
           ^^^^^^^^^^^^^^^^^^^^^^^^^^
  File "/opt/airflow/dags/ml_pipeline.py", line 69, in evaluate_model
    X_test = pd.DataFrame(X_test, columns=['sepal length (cm)', 'sepal width (cm)', 'petal length (cm)', 'petal width (cm)'])
             ^^^^^^^^^^^^^^^^^^^^^^^^^^^^^^^^^^^^^^^^^^^^^^^^^^^^^^^^^^^^^^^^^^^^^^^^^^^^^^^^^^^^^^^^^^^^^^^^^^^^^^^^^^^^^^^^
  File "/home/airflow/.local/lib/python3.12/site-packages/pandas/core/frame.py", line 841, in __init__
    raise ValueError("DataFrame constructor not properly called!")
ValueError: DataFrame constructor not properly called!
[2024-09-01T15:33:58.884+0000] {logging_mixin.py:190} INFO - Task instance in failure state
[2024-09-01T15:33:58.885+0000] {logging_mixin.py:190} INFO - Task start:2024-09-01 15:33:58.425725+00:00 end:2024-09-01 15:33:58.884321+00:00 duration:0.458596
[2024-09-01T15:33:58.886+0000] {logging_mixin.py:190} INFO - Task:<Task(PythonOperator): evaluate_model> dag:<DAG: ml_pipeline> dagrun:<DagRun ml_pipeline @ 2024-09-01 15:33:44.449486+00:00: manual__2024-09-01T15:33:44.449486+00:00, state:running, queued_at: 2024-09-01 15:33:44.479489+00:00. externally triggered: True>
[2024-09-01T15:33:58.886+0000] {logging_mixin.py:190} INFO - Failure caused by DataFrame constructor not properly called!
[2024-09-01T15:33:58.887+0000] {taskinstance.py:1225} INFO - Marking task as UP_FOR_RETRY. dag_id=ml_pipeline, task_id=evaluate_model, run_id=manual__2024-09-01T15:33:44.449486+00:00, execution_date=20240901T153344, start_date=20240901T153358, end_date=20240901T153358
[2024-09-01T15:33:58.908+0000] {taskinstance.py:340} INFO - ::group::Post task execution logs
[2024-09-01T15:33:58.909+0000] {standard_task_runner.py:124} ERROR - Failed to execute job 97 for task evaluate_model (DataFrame constructor not properly called!; 1235)
Traceback (most recent call last):
  File "/home/airflow/.local/lib/python3.12/site-packages/airflow/task/task_runner/standard_task_runner.py", line 117, in _start_by_fork
    ret = args.func(args, dag=self.dag)
          ^^^^^^^^^^^^^^^^^^^^^^^^^^^^^
  File "/home/airflow/.local/lib/python3.12/site-packages/airflow/cli/cli_config.py", line 49, in command
    return func(*args, **kwargs)
           ^^^^^^^^^^^^^^^^^^^^^
  File "/home/airflow/.local/lib/python3.12/site-packages/airflow/utils/cli.py", line 115, in wrapper
    return f(*args, **kwargs)
           ^^^^^^^^^^^^^^^^^^
  File "/home/airflow/.local/lib/python3.12/site-packages/airflow/cli/commands/task_command.py", line 483, in task_run
    task_return_code = _run_task_by_selected_method(args, _dag, ti)
                       ^^^^^^^^^^^^^^^^^^^^^^^^^^^^^^^^^^^^^^^^^^^^
  File "/home/airflow/.local/lib/python3.12/site-packages/airflow/cli/commands/task_command.py", line 256, in _run_task_by_selected_method
    return _run_raw_task(args, ti)
           ^^^^^^^^^^^^^^^^^^^^^^^
  File "/home/airflow/.local/lib/python3.12/site-packages/airflow/cli/commands/task_command.py", line 341, in _run_raw_task
    return ti._run_raw_task(
           ^^^^^^^^^^^^^^^^^
  File "/home/airflow/.local/lib/python3.12/site-packages/airflow/utils/session.py", line 97, in wrapper
    return func(*args, session=session, **kwargs)
           ^^^^^^^^^^^^^^^^^^^^^^^^^^^^^^^^^^^^^^
  File "/home/airflow/.local/lib/python3.12/site-packages/airflow/models/taskinstance.py", line 2995, in _run_raw_task
    return _run_raw_task(
           ^^^^^^^^^^^^^^
  File "/home/airflow/.local/lib/python3.12/site-packages/airflow/models/taskinstance.py", line 273, in _run_raw_task
    TaskInstance._execute_task_with_callbacks(
  File "/home/airflow/.local/lib/python3.12/site-packages/airflow/models/taskinstance.py", line 3149, in _execute_task_with_callbacks
    result = self._execute_task(context, task_orig)
             ^^^^^^^^^^^^^^^^^^^^^^^^^^^^^^^^^^^^^^
  File "/home/airflow/.local/lib/python3.12/site-packages/airflow/models/taskinstance.py", line 3173, in _execute_task
    return _execute_task(self, context, task_orig)
           ^^^^^^^^^^^^^^^^^^^^^^^^^^^^^^^^^^^^^^^
  File "/home/airflow/.local/lib/python3.12/site-packages/airflow/models/taskinstance.py", line 767, in _execute_task
    result = _execute_callable(context=context, **execute_callable_kwargs)
             ^^^^^^^^^^^^^^^^^^^^^^^^^^^^^^^^^^^^^^^^^^^^^^^^^^^^^^^^^^^^^
  File "/home/airflow/.local/lib/python3.12/site-packages/airflow/models/taskinstance.py", line 733, in _execute_callable
    return ExecutionCallableRunner(
           ^^^^^^^^^^^^^^^^^^^^^^^^
  File "/home/airflow/.local/lib/python3.12/site-packages/airflow/utils/operator_helpers.py", line 252, in run
    return self.func(*args, **kwargs)
           ^^^^^^^^^^^^^^^^^^^^^^^^^^
  File "/home/airflow/.local/lib/python3.12/site-packages/airflow/models/baseoperator.py", line 406, in wrapper
    return func(self, *args, **kwargs)
           ^^^^^^^^^^^^^^^^^^^^^^^^^^^
  File "/home/airflow/.local/lib/python3.12/site-packages/airflow/operators/python.py", line 238, in execute
    return_value = self.execute_callable()
                   ^^^^^^^^^^^^^^^^^^^^^^^
  File "/home/airflow/.local/lib/python3.12/site-packages/airflow/operators/python.py", line 256, in execute_callable
    return runner.run(*self.op_args, **self.op_kwargs)
           ^^^^^^^^^^^^^^^^^^^^^^^^^^^^^^^^^^^^^^^^^^^
  File "/home/airflow/.local/lib/python3.12/site-packages/airflow/utils/operator_helpers.py", line 252, in run
    return self.func(*args, **kwargs)
           ^^^^^^^^^^^^^^^^^^^^^^^^^^
  File "/opt/airflow/dags/ml_pipeline.py", line 69, in evaluate_model
    X_test = pd.DataFrame(X_test, columns=['sepal length (cm)', 'sepal width (cm)', 'petal length (cm)', 'petal width (cm)'])
             ^^^^^^^^^^^^^^^^^^^^^^^^^^^^^^^^^^^^^^^^^^^^^^^^^^^^^^^^^^^^^^^^^^^^^^^^^^^^^^^^^^^^^^^^^^^^^^^^^^^^^^^^^^^^^^^^
  File "/home/airflow/.local/lib/python3.12/site-packages/pandas/core/frame.py", line 841, in __init__
    raise ValueError("DataFrame constructor not properly called!")
ValueError: DataFrame constructor not properly called!
[2024-09-01T15:33:58.957+0000] {local_task_job_runner.py:261} INFO - Task exited with return code 1
[2024-09-01T15:33:58.985+0000] {taskinstance.py:3891} INFO - 0 downstream tasks scheduled from follow-on schedule check
[2024-09-01T15:33:58.988+0000] {local_task_job_runner.py:240} INFO - ::endgroup::
