[2024-09-01T12:59:12.978+0000] {local_task_job_runner.py:123} INFO - ::group::Pre task execution logs
[2024-09-01T12:59:13.122+0000] {taskinstance.py:2603} INFO - Dependencies all met for dep_context=non-requeueable deps ti=<TaskInstance: ml_pipeline.load_data manual__2024-09-01T12:59:08.343464+00:00 [queued]>
[2024-09-01T12:59:13.130+0000] {taskinstance.py:2603} INFO - Dependencies all met for dep_context=requeueable deps ti=<TaskInstance: ml_pipeline.load_data manual__2024-09-01T12:59:08.343464+00:00 [queued]>
[2024-09-01T12:59:13.131+0000] {taskinstance.py:2856} INFO - Starting attempt 1 of 2
[2024-09-01T12:59:13.145+0000] {taskinstance.py:2879} INFO - Executing <Task(PythonOperator): load_data> on 2024-09-01 12:59:08.343464+00:00
[2024-09-01T12:59:13.155+0000] {warnings.py:112} WARNING - /home/***/.local/lib/python3.12/site-packages/***/task/task_runner/standard_task_runner.py:70: DeprecationWarning: This process (pid=373) is multi-threaded, use of fork() may lead to deadlocks in the child.
  pid = os.fork()

[2024-09-01T12:59:13.157+0000] {standard_task_runner.py:72} INFO - Started process 382 to run task
[2024-09-01T12:59:13.157+0000] {standard_task_runner.py:104} INFO - Running: ['***', 'tasks', 'run', 'ml_pipeline', 'load_data', 'manual__2024-09-01T12:59:08.343464+00:00', '--job-id', '19', '--raw', '--subdir', 'DAGS_FOLDER/ml_pipeline.py', '--cfg-path', '/tmp/tmpnx4wf3qd']
[2024-09-01T12:59:13.159+0000] {standard_task_runner.py:105} INFO - Job 19: Subtask load_data
[2024-09-01T12:59:13.204+0000] {task_command.py:467} INFO - Running <TaskInstance: ml_pipeline.load_data manual__2024-09-01T12:59:08.343464+00:00 [running]> on host bb7792a7b380
[2024-09-01T12:59:13.280+0000] {taskinstance.py:3122} INFO - Exporting env vars: AIRFLOW_CTX_DAG_OWNER='***' AIRFLOW_CTX_DAG_ID='ml_pipeline' AIRFLOW_CTX_TASK_ID='load_data' AIRFLOW_CTX_EXECUTION_DATE='2024-09-01T12:59:08.343464+00:00' AIRFLOW_CTX_TRY_NUMBER='1' AIRFLOW_CTX_DAG_RUN_ID='manual__2024-09-01T12:59:08.343464+00:00'
[2024-09-01T12:59:13.282+0000] {logging_mixin.py:190} INFO - Task instance is in running state
[2024-09-01T12:59:13.282+0000] {logging_mixin.py:190} INFO -  Previous state of the Task instance: queued
[2024-09-01T12:59:13.283+0000] {logging_mixin.py:190} INFO - Current task name:load_data state:running start_date:2024-09-01 12:59:13.123308+00:00
[2024-09-01T12:59:13.283+0000] {logging_mixin.py:190} INFO - Dag name:ml_pipeline and current dag run status:running
[2024-09-01T12:59:13.284+0000] {taskinstance.py:731} INFO - ::endgroup::
[2024-09-01T12:59:13.303+0000] {taskinstance.py:3301} ERROR - Task failed with exception
Traceback (most recent call last):
  File "/home/airflow/.local/lib/python3.12/site-packages/airflow/models/taskinstance.py", line 767, in _execute_task
    result = _execute_callable(context=context, **execute_callable_kwargs)
             ^^^^^^^^^^^^^^^^^^^^^^^^^^^^^^^^^^^^^^^^^^^^^^^^^^^^^^^^^^^^^
  File "/home/airflow/.local/lib/python3.12/site-packages/airflow/models/taskinstance.py", line 733, in _execute_callable
    return ExecutionCallableRunner(
           ^^^^^^^^^^^^^^^^^^^^^^^^
  File "/home/airflow/.local/lib/python3.12/site-packages/airflow/utils/operator_helpers.py", line 252, in run
    return self.func(*args, **kwargs)
           ^^^^^^^^^^^^^^^^^^^^^^^^^^
  File "/home/airflow/.local/lib/python3.12/site-packages/airflow/models/baseoperator.py", line 406, in wrapper
    return func(self, *args, **kwargs)
           ^^^^^^^^^^^^^^^^^^^^^^^^^^^
  File "/home/airflow/.local/lib/python3.12/site-packages/airflow/operators/python.py", line 238, in execute
    return_value = self.execute_callable()
                   ^^^^^^^^^^^^^^^^^^^^^^^
  File "/home/airflow/.local/lib/python3.12/site-packages/airflow/operators/python.py", line 256, in execute_callable
    return runner.run(*self.op_args, **self.op_kwargs)
           ^^^^^^^^^^^^^^^^^^^^^^^^^^^^^^^^^^^^^^^^^^^
  File "/home/airflow/.local/lib/python3.12/site-packages/airflow/utils/operator_helpers.py", line 252, in run
    return self.func(*args, **kwargs)
           ^^^^^^^^^^^^^^^^^^^^^^^^^^
  File "/opt/airflow/dags/ml_pipeline.py", line 19, in load_data
    data.to_csv(DATA_PATH, index=False)
  File "/home/airflow/.local/lib/python3.12/site-packages/pandas/core/generic.py", line 3902, in to_csv
    return DataFrameRenderer(formatter).to_csv(
           ^^^^^^^^^^^^^^^^^^^^^^^^^^^^^^^^^^^^
  File "/home/airflow/.local/lib/python3.12/site-packages/pandas/io/formats/format.py", line 1152, in to_csv
    csv_formatter.save()
  File "/home/airflow/.local/lib/python3.12/site-packages/pandas/io/formats/csvs.py", line 247, in save
    with get_handle(
         ^^^^^^^^^^^
  File "/home/airflow/.local/lib/python3.12/site-packages/pandas/io/common.py", line 739, in get_handle
    check_parent_directory(str(handle))
  File "/home/airflow/.local/lib/python3.12/site-packages/pandas/io/common.py", line 604, in check_parent_directory
    raise OSError(rf"Cannot save file into a non-existent directory: '{parent}'")
OSError: Cannot save file into a non-existent directory: 'Airflow/data'
[2024-09-01T12:59:13.325+0000] {logging_mixin.py:190} INFO - Task instance in failure state
[2024-09-01T12:59:13.325+0000] {logging_mixin.py:190} INFO - Task start:2024-09-01 12:59:13.123308+00:00 end:2024-09-01 12:59:13.324824+00:00 duration:0.201516
[2024-09-01T12:59:13.326+0000] {logging_mixin.py:190} INFO - Task:<Task(PythonOperator): load_data> dag:<DAG: ml_pipeline> dagrun:<DagRun ml_pipeline @ 2024-09-01 12:59:08.343464+00:00: manual__2024-09-01T12:59:08.343464+00:00, state:running, queued_at: 2024-09-01 12:59:08.395412+00:00. externally triggered: True>
[2024-09-01T12:59:13.327+0000] {logging_mixin.py:190} INFO - Failure caused by Cannot save file into a non-existent directory: 'Airflow/data'
[2024-09-01T12:59:13.327+0000] {taskinstance.py:1225} INFO - Marking task as UP_FOR_RETRY. dag_id=ml_pipeline, task_id=load_data, run_id=manual__2024-09-01T12:59:08.343464+00:00, execution_date=20240901T125908, start_date=20240901T125913, end_date=20240901T125913
[2024-09-01T12:59:13.344+0000] {taskinstance.py:340} INFO - ::group::Post task execution logs
[2024-09-01T12:59:13.345+0000] {standard_task_runner.py:124} ERROR - Failed to execute job 19 for task load_data (Cannot save file into a non-existent directory: 'Airflow/data'; 382)
Traceback (most recent call last):
  File "/home/airflow/.local/lib/python3.12/site-packages/airflow/task/task_runner/standard_task_runner.py", line 117, in _start_by_fork
    ret = args.func(args, dag=self.dag)
          ^^^^^^^^^^^^^^^^^^^^^^^^^^^^^
  File "/home/airflow/.local/lib/python3.12/site-packages/airflow/cli/cli_config.py", line 49, in command
    return func(*args, **kwargs)
           ^^^^^^^^^^^^^^^^^^^^^
  File "/home/airflow/.local/lib/python3.12/site-packages/airflow/utils/cli.py", line 115, in wrapper
    return f(*args, **kwargs)
           ^^^^^^^^^^^^^^^^^^
  File "/home/airflow/.local/lib/python3.12/site-packages/airflow/cli/commands/task_command.py", line 483, in task_run
    task_return_code = _run_task_by_selected_method(args, _dag, ti)
                       ^^^^^^^^^^^^^^^^^^^^^^^^^^^^^^^^^^^^^^^^^^^^
  File "/home/airflow/.local/lib/python3.12/site-packages/airflow/cli/commands/task_command.py", line 256, in _run_task_by_selected_method
    return _run_raw_task(args, ti)
           ^^^^^^^^^^^^^^^^^^^^^^^
  File "/home/airflow/.local/lib/python3.12/site-packages/airflow/cli/commands/task_command.py", line 341, in _run_raw_task
    return ti._run_raw_task(
           ^^^^^^^^^^^^^^^^^
  File "/home/airflow/.local/lib/python3.12/site-packages/airflow/utils/session.py", line 97, in wrapper
    return func(*args, session=session, **kwargs)
           ^^^^^^^^^^^^^^^^^^^^^^^^^^^^^^^^^^^^^^
  File "/home/airflow/.local/lib/python3.12/site-packages/airflow/models/taskinstance.py", line 2995, in _run_raw_task
    return _run_raw_task(
           ^^^^^^^^^^^^^^
  File "/home/airflow/.local/lib/python3.12/site-packages/airflow/models/taskinstance.py", line 273, in _run_raw_task
    TaskInstance._execute_task_with_callbacks(
  File "/home/airflow/.local/lib/python3.12/site-packages/airflow/models/taskinstance.py", line 3149, in _execute_task_with_callbacks
    result = self._execute_task(context, task_orig)
             ^^^^^^^^^^^^^^^^^^^^^^^^^^^^^^^^^^^^^^
  File "/home/airflow/.local/lib/python3.12/site-packages/airflow/models/taskinstance.py", line 3173, in _execute_task
    return _execute_task(self, context, task_orig)
           ^^^^^^^^^^^^^^^^^^^^^^^^^^^^^^^^^^^^^^^
  File "/home/airflow/.local/lib/python3.12/site-packages/airflow/models/taskinstance.py", line 767, in _execute_task
    result = _execute_callable(context=context, **execute_callable_kwargs)
             ^^^^^^^^^^^^^^^^^^^^^^^^^^^^^^^^^^^^^^^^^^^^^^^^^^^^^^^^^^^^^
  File "/home/airflow/.local/lib/python3.12/site-packages/airflow/models/taskinstance.py", line 733, in _execute_callable
    return ExecutionCallableRunner(
           ^^^^^^^^^^^^^^^^^^^^^^^^
  File "/home/airflow/.local/lib/python3.12/site-packages/airflow/utils/operator_helpers.py", line 252, in run
    return self.func(*args, **kwargs)
           ^^^^^^^^^^^^^^^^^^^^^^^^^^
  File "/home/airflow/.local/lib/python3.12/site-packages/airflow/models/baseoperator.py", line 406, in wrapper
    return func(self, *args, **kwargs)
           ^^^^^^^^^^^^^^^^^^^^^^^^^^^
  File "/home/airflow/.local/lib/python3.12/site-packages/airflow/operators/python.py", line 238, in execute
    return_value = self.execute_callable()
                   ^^^^^^^^^^^^^^^^^^^^^^^
  File "/home/airflow/.local/lib/python3.12/site-packages/airflow/operators/python.py", line 256, in execute_callable
    return runner.run(*self.op_args, **self.op_kwargs)
           ^^^^^^^^^^^^^^^^^^^^^^^^^^^^^^^^^^^^^^^^^^^
  File "/home/airflow/.local/lib/python3.12/site-packages/airflow/utils/operator_helpers.py", line 252, in run
    return self.func(*args, **kwargs)
           ^^^^^^^^^^^^^^^^^^^^^^^^^^
  File "/opt/airflow/dags/ml_pipeline.py", line 19, in load_data
    data.to_csv(DATA_PATH, index=False)
  File "/home/airflow/.local/lib/python3.12/site-packages/pandas/core/generic.py", line 3902, in to_csv
    return DataFrameRenderer(formatter).to_csv(
           ^^^^^^^^^^^^^^^^^^^^^^^^^^^^^^^^^^^^
  File "/home/airflow/.local/lib/python3.12/site-packages/pandas/io/formats/format.py", line 1152, in to_csv
    csv_formatter.save()
  File "/home/airflow/.local/lib/python3.12/site-packages/pandas/io/formats/csvs.py", line 247, in save
    with get_handle(
         ^^^^^^^^^^^
  File "/home/airflow/.local/lib/python3.12/site-packages/pandas/io/common.py", line 739, in get_handle
    check_parent_directory(str(handle))
  File "/home/airflow/.local/lib/python3.12/site-packages/pandas/io/common.py", line 604, in check_parent_directory
    raise OSError(rf"Cannot save file into a non-existent directory: '{parent}'")
OSError: Cannot save file into a non-existent directory: 'Airflow/data'
[2024-09-01T12:59:13.373+0000] {local_task_job_runner.py:261} INFO - Task exited with return code 1
[2024-09-01T12:59:13.394+0000] {taskinstance.py:3891} INFO - 0 downstream tasks scheduled from follow-on schedule check
[2024-09-01T12:59:13.397+0000] {local_task_job_runner.py:240} INFO - ::endgroup::
