[2024-09-01T12:46:58.415+0000] {local_task_job_runner.py:123} INFO - ::group::Pre task execution logs
[2024-09-01T12:46:58.432+0000] {taskinstance.py:2603} INFO - Dependencies all met for dep_context=non-requeueable deps ti=<TaskInstance: ml_pipeline.load_data manual__2024-09-01T12:46:51.810840+00:00 [queued]>
[2024-09-01T12:46:58.441+0000] {taskinstance.py:2603} INFO - Dependencies all met for dep_context=requeueable deps ti=<TaskInstance: ml_pipeline.load_data manual__2024-09-01T12:46:51.810840+00:00 [queued]>
[2024-09-01T12:46:58.442+0000] {taskinstance.py:2856} INFO - Starting attempt 1 of 2
[2024-09-01T12:46:58.456+0000] {taskinstance.py:2879} INFO - Executing <Task(PythonOperator): load_data> on 2024-09-01 12:46:51.810840+00:00
[2024-09-01T12:46:58.465+0000] {warnings.py:112} WARNING - /home/***/.local/lib/python3.12/site-packages/***/task/task_runner/standard_task_runner.py:70: DeprecationWarning: This process (pid=77) is multi-threaded, use of fork() may lead to deadlocks in the child.
  pid = os.fork()

[2024-09-01T12:46:58.466+0000] {standard_task_runner.py:104} INFO - Running: ['***', 'tasks', 'run', 'ml_pipeline', 'load_data', 'manual__2024-09-01T12:46:51.810840+00:00', '--job-id', '9', '--raw', '--subdir', 'DAGS_FOLDER/ml_pipeline.py', '--cfg-path', '/tmp/tmpntuz61bk']
[2024-09-01T12:46:58.467+0000] {standard_task_runner.py:72} INFO - Started process 86 to run task
[2024-09-01T12:46:58.467+0000] {standard_task_runner.py:105} INFO - Job 9: Subtask load_data
[2024-09-01T12:46:58.516+0000] {task_command.py:467} INFO - Running <TaskInstance: ml_pipeline.load_data manual__2024-09-01T12:46:51.810840+00:00 [running]> on host bb7792a7b380
[2024-09-01T12:46:58.606+0000] {taskinstance.py:3122} INFO - Exporting env vars: AIRFLOW_CTX_DAG_OWNER='***' AIRFLOW_CTX_DAG_ID='ml_pipeline' AIRFLOW_CTX_TASK_ID='load_data' AIRFLOW_CTX_EXECUTION_DATE='2024-09-01T12:46:51.810840+00:00' AIRFLOW_CTX_TRY_NUMBER='1' AIRFLOW_CTX_DAG_RUN_ID='manual__2024-09-01T12:46:51.810840+00:00'
[2024-09-01T12:46:58.608+0000] {logging_mixin.py:190} INFO - Task instance is in running state
[2024-09-01T12:46:58.609+0000] {logging_mixin.py:190} INFO -  Previous state of the Task instance: queued
[2024-09-01T12:46:58.610+0000] {logging_mixin.py:190} INFO - Current task name:load_data state:running start_date:2024-09-01 12:46:58.433456+00:00
[2024-09-01T12:46:58.610+0000] {logging_mixin.py:190} INFO - Dag name:ml_pipeline and current dag run status:running
[2024-09-01T12:46:58.611+0000] {taskinstance.py:731} INFO - ::endgroup::
[2024-09-01T12:46:58.624+0000] {taskinstance.py:3301} ERROR - Task failed with exception
Traceback (most recent call last):
  File "/home/airflow/.local/lib/python3.12/site-packages/sklearn/utils/_bunch.py", line 54, in __getattr__
    return self[key]
           ~~~~^^^^^
  File "/home/airflow/.local/lib/python3.12/site-packages/sklearn/utils/_bunch.py", line 39, in __getitem__
    return super().__getitem__(key)
           ^^^^^^^^^^^^^^^^^^^^^^^^
KeyError: 'features_names'

During handling of the above exception, another exception occurred:

Traceback (most recent call last):
  File "/home/airflow/.local/lib/python3.12/site-packages/airflow/models/taskinstance.py", line 767, in _execute_task
    result = _execute_callable(context=context, **execute_callable_kwargs)
             ^^^^^^^^^^^^^^^^^^^^^^^^^^^^^^^^^^^^^^^^^^^^^^^^^^^^^^^^^^^^^
  File "/home/airflow/.local/lib/python3.12/site-packages/airflow/models/taskinstance.py", line 733, in _execute_callable
    return ExecutionCallableRunner(
           ^^^^^^^^^^^^^^^^^^^^^^^^
  File "/home/airflow/.local/lib/python3.12/site-packages/airflow/utils/operator_helpers.py", line 252, in run
    return self.func(*args, **kwargs)
           ^^^^^^^^^^^^^^^^^^^^^^^^^^
  File "/home/airflow/.local/lib/python3.12/site-packages/airflow/models/baseoperator.py", line 406, in wrapper
    return func(self, *args, **kwargs)
           ^^^^^^^^^^^^^^^^^^^^^^^^^^^
  File "/home/airflow/.local/lib/python3.12/site-packages/airflow/operators/python.py", line 238, in execute
    return_value = self.execute_callable()
                   ^^^^^^^^^^^^^^^^^^^^^^^
  File "/home/airflow/.local/lib/python3.12/site-packages/airflow/operators/python.py", line 256, in execute_callable
    return runner.run(*self.op_args, **self.op_kwargs)
           ^^^^^^^^^^^^^^^^^^^^^^^^^^^^^^^^^^^^^^^^^^^
  File "/home/airflow/.local/lib/python3.12/site-packages/airflow/utils/operator_helpers.py", line 252, in run
    return self.func(*args, **kwargs)
           ^^^^^^^^^^^^^^^^^^^^^^^^^^
  File "/opt/airflow/dags/ml_pipeline.py", line 14, in load_data
    data = pd.DataFrame(data=iris.data, columns=iris.features_names)
                                                ^^^^^^^^^^^^^^^^^^^
  File "/home/airflow/.local/lib/python3.12/site-packages/sklearn/utils/_bunch.py", line 56, in __getattr__
    raise AttributeError(key)
AttributeError: features_names. Did you mean: 'feature_names'?
[2024-09-01T12:46:58.644+0000] {logging_mixin.py:190} INFO - Task instance in failure state
[2024-09-01T12:46:58.644+0000] {logging_mixin.py:190} INFO - Task start:2024-09-01 12:46:58.433456+00:00 end:2024-09-01 12:46:58.643612+00:00 duration:0.210156
[2024-09-01T12:46:58.645+0000] {logging_mixin.py:190} INFO - Task:<Task(PythonOperator): load_data> dag:<DAG: ml_pipeline> dagrun:<DagRun ml_pipeline @ 2024-09-01 12:46:51.810840+00:00: manual__2024-09-01T12:46:51.810840+00:00, state:running, queued_at: 2024-09-01 12:46:51.859747+00:00. externally triggered: True>
[2024-09-01T12:46:58.645+0000] {logging_mixin.py:190} INFO - Failure caused by features_names
[2024-09-01T12:46:58.646+0000] {taskinstance.py:1225} INFO - Marking task as UP_FOR_RETRY. dag_id=ml_pipeline, task_id=load_data, run_id=manual__2024-09-01T12:46:51.810840+00:00, execution_date=20240901T124651, start_date=20240901T124658, end_date=20240901T124658
[2024-09-01T12:46:58.664+0000] {taskinstance.py:340} INFO - ::group::Post task execution logs
[2024-09-01T12:46:58.665+0000] {standard_task_runner.py:124} ERROR - Failed to execute job 9 for task load_data (features_names; 86)
Traceback (most recent call last):
  File "/home/airflow/.local/lib/python3.12/site-packages/sklearn/utils/_bunch.py", line 54, in __getattr__
    return self[key]
           ~~~~^^^^^
  File "/home/airflow/.local/lib/python3.12/site-packages/sklearn/utils/_bunch.py", line 39, in __getitem__
    return super().__getitem__(key)
           ^^^^^^^^^^^^^^^^^^^^^^^^
KeyError: 'features_names'

During handling of the above exception, another exception occurred:

Traceback (most recent call last):
  File "/home/airflow/.local/lib/python3.12/site-packages/airflow/task/task_runner/standard_task_runner.py", line 117, in _start_by_fork
    ret = args.func(args, dag=self.dag)
          ^^^^^^^^^^^^^^^^^^^^^^^^^^^^^
  File "/home/airflow/.local/lib/python3.12/site-packages/airflow/cli/cli_config.py", line 49, in command
    return func(*args, **kwargs)
           ^^^^^^^^^^^^^^^^^^^^^
  File "/home/airflow/.local/lib/python3.12/site-packages/airflow/utils/cli.py", line 115, in wrapper
    return f(*args, **kwargs)
           ^^^^^^^^^^^^^^^^^^
  File "/home/airflow/.local/lib/python3.12/site-packages/airflow/cli/commands/task_command.py", line 483, in task_run
    task_return_code = _run_task_by_selected_method(args, _dag, ti)
                       ^^^^^^^^^^^^^^^^^^^^^^^^^^^^^^^^^^^^^^^^^^^^
  File "/home/airflow/.local/lib/python3.12/site-packages/airflow/cli/commands/task_command.py", line 256, in _run_task_by_selected_method
    return _run_raw_task(args, ti)
           ^^^^^^^^^^^^^^^^^^^^^^^
  File "/home/airflow/.local/lib/python3.12/site-packages/airflow/cli/commands/task_command.py", line 341, in _run_raw_task
    return ti._run_raw_task(
           ^^^^^^^^^^^^^^^^^
  File "/home/airflow/.local/lib/python3.12/site-packages/airflow/utils/session.py", line 97, in wrapper
    return func(*args, session=session, **kwargs)
           ^^^^^^^^^^^^^^^^^^^^^^^^^^^^^^^^^^^^^^
  File "/home/airflow/.local/lib/python3.12/site-packages/airflow/models/taskinstance.py", line 2995, in _run_raw_task
    return _run_raw_task(
           ^^^^^^^^^^^^^^
  File "/home/airflow/.local/lib/python3.12/site-packages/airflow/models/taskinstance.py", line 273, in _run_raw_task
    TaskInstance._execute_task_with_callbacks(
  File "/home/airflow/.local/lib/python3.12/site-packages/airflow/models/taskinstance.py", line 3149, in _execute_task_with_callbacks
    result = self._execute_task(context, task_orig)
             ^^^^^^^^^^^^^^^^^^^^^^^^^^^^^^^^^^^^^^
  File "/home/airflow/.local/lib/python3.12/site-packages/airflow/models/taskinstance.py", line 3173, in _execute_task
    return _execute_task(self, context, task_orig)
           ^^^^^^^^^^^^^^^^^^^^^^^^^^^^^^^^^^^^^^^
  File "/home/airflow/.local/lib/python3.12/site-packages/airflow/models/taskinstance.py", line 767, in _execute_task
    result = _execute_callable(context=context, **execute_callable_kwargs)
             ^^^^^^^^^^^^^^^^^^^^^^^^^^^^^^^^^^^^^^^^^^^^^^^^^^^^^^^^^^^^^
  File "/home/airflow/.local/lib/python3.12/site-packages/airflow/models/taskinstance.py", line 733, in _execute_callable
    return ExecutionCallableRunner(
           ^^^^^^^^^^^^^^^^^^^^^^^^
  File "/home/airflow/.local/lib/python3.12/site-packages/airflow/utils/operator_helpers.py", line 252, in run
    return self.func(*args, **kwargs)
           ^^^^^^^^^^^^^^^^^^^^^^^^^^
  File "/home/airflow/.local/lib/python3.12/site-packages/airflow/models/baseoperator.py", line 406, in wrapper
    return func(self, *args, **kwargs)
           ^^^^^^^^^^^^^^^^^^^^^^^^^^^
  File "/home/airflow/.local/lib/python3.12/site-packages/airflow/operators/python.py", line 238, in execute
    return_value = self.execute_callable()
                   ^^^^^^^^^^^^^^^^^^^^^^^
  File "/home/airflow/.local/lib/python3.12/site-packages/airflow/operators/python.py", line 256, in execute_callable
    return runner.run(*self.op_args, **self.op_kwargs)
           ^^^^^^^^^^^^^^^^^^^^^^^^^^^^^^^^^^^^^^^^^^^
  File "/home/airflow/.local/lib/python3.12/site-packages/airflow/utils/operator_helpers.py", line 252, in run
    return self.func(*args, **kwargs)
           ^^^^^^^^^^^^^^^^^^^^^^^^^^
  File "/opt/airflow/dags/ml_pipeline.py", line 14, in load_data
    data = pd.DataFrame(data=iris.data, columns=iris.features_names)
                                                ^^^^^^^^^^^^^^^^^^^
  File "/home/airflow/.local/lib/python3.12/site-packages/sklearn/utils/_bunch.py", line 56, in __getattr__
    raise AttributeError(key)
AttributeError: features_names. Did you mean: 'feature_names'?
[2024-09-01T12:46:58.684+0000] {local_task_job_runner.py:261} INFO - Task exited with return code 1
[2024-09-01T12:46:58.708+0000] {taskinstance.py:3891} INFO - 0 downstream tasks scheduled from follow-on schedule check
[2024-09-01T12:46:58.710+0000] {local_task_job_runner.py:240} INFO - ::endgroup::
